Workbook
Name _________C: '[1]B S'!#REF!
Name _________C: '[1]B S'!#REF!
Name _________C: '[1]B S'!#REF!
Name _________C: '[1]B S'!#REF!
Name _________ESC1: #REF!
Name _________ESC1: #REF!
Name _________ESC1: #REF!
Name _________ESC1: #REF!
Name _________TB1: [2]LIST!$C$123:$P$132
Name ________C: '[1]B S'!#REF!
Name ________C: '[1]B S'!#REF!
Name ________C: '[1]B S'!#REF!
Name ________C: '[1]B S'!#REF!
Name ________ESC1: #REF!
Name ________ESC1: #REF!
Name ________ESC1: #REF!
Name ________ESC1: #REF!
Name ________TB1: [2]LIST!$C$123:$P$132
Name _______C: '[1]B S'!#REF!
Name _______C: '[1]B S'!#REF!
Name _______C: '[1]B S'!#REF!
Name _______C: '[1]B S'!#REF!
Name _______ESC1: #REF!
Name _______ESC1: #REF!
Name _______ESC1: #REF!
Name _______ESC1: #REF!
Name _______TB1: [2]LIST!$C$123:$P$132
Name ______C: '[1]B S'!#REF!
Name ______C: '[1]B S'!#REF!
Name ______C: '[1]B S'!#REF!
Name ______C: '[1]B S'!#REF!
Name ______ESC1: #REF!
Name ______ESC1: #REF!
Name ______ESC1: #REF!
Name ______ESC1: #REF!
Name ______TB1: [2]LIST!$C$123:$P$132
Name _____C: '[1]B S'!#REF!
Name _____C: '[1]B S'!#REF!
Name _____C: '[1]B S'!#REF!
Name _____C: '[1]B S'!#REF!
Name _____ESC1: #REF!
Name _____ESC1: #REF!
Name _____ESC1: #REF!
Name _____ESC1: #REF!
Name _____TB1: [2]LIST!$C$123:$P$132
Name ____C: '[1]B S'!#REF!
Name ____C: '[1]B S'!#REF!
Name ____C: '[1]B S'!#REF!
Name ____C: '[1]B S'!#REF!
Name ____ESC1: #REF!
Name ____ESC1: #REF!
Name ____ESC1: #REF!
Name ____ESC1: #REF!
Name ____TB1: [2]LIST!$C$123:$P$132
Name ___C: '[1]B S'!#REF!
Name ___C: '[1]B S'!#REF!
Name ___C: '[1]B S'!#REF!
Name ___C: '[1]B S'!#REF!
Name ___ESC1: #REF!
Name ___ESC1: #REF!

Sheet Analysis 20-21
A1: Overall Variance analysis
A3: Particulars | B3: 2019-20 | D3: 2020-21 | F3: Variance | G3: Percentage change over previous year
B4: Actual | C4: Percentage on sales | D4: Actual | E4: Percentage on sales
A5: Revenue:
A6: Sales | B6: 3.2895775e+08 | D6: 2.587758e+08 | F6: =D6-B6 -> -70181952 | G6: =F6/B6 -> -0.2133464
A7: other Income | B7: 10903544 | D7: 5691621 | F7: =D7-B7 -> -5211923 | G7: =F7/B7 -> -0.47800266
F8: =F6+F7 -> -75393875
A9: Expenses
A10: Construction and operating
A11: Construction Material Consumed | B11: 69930964 | C11: =B11/B6 -> 0.21258342 | D11: 81386421 | E11: =D11/D6 -> 0.31450554 | F11: =B11-D11 -> -11455457 | G11: =E11-C11 -> 0.10192212
A12: Wages paid | B12: 102541739 | C12: =B12/B6 -> 0.31171705 | D12: 95817327 | E12: =D12/D6 -> 0.37027159 | F12: =B12-D12 -> 6724412.3 | G12: =E12-C12 -> 0.058554544
A13: Construction Work Expenses | B13: 41641425 | C13: =B13/B6 -> 0.12658594 | D13: 32380431 | E13: =D13/D6 -> 0.12512929 | F13: =B13-D13 -> 9260993.7 | G13: =E13-C13 -> -0.0014566492
A14: EMPLOYEE BENEFITS EXPENSE | F14: =B14-D14 -> 0 | G14: =E14-C14 -> 0
A15: Salaries and wages | B15: 29509489 | C15: =B15/B6 -> 0.089706016 | D15: 27106724 | E15: =D15/D6 -> 0.10474984 | F15: =B15-D15 -> 2402765 | G15: =E15-C15 -> 0.015043827
A16: Contribution to PF and other funds | B16: 4628619 | C16: =B16/B6 -> 0.014070558 | D16: 4023696 | F16: =B16-D16 -> 604923 | G16: =E16-C16 -> -0.014070558
A17: Director’s Remuneration | B17: 3780000 | C17: =B17/ B6 -> 0.011490837 | D17: 3677400 | E17: =D17/D6 -> 0.014210757 | F17: =B17-D17 -> 102600 | G17: =E17-C17 -> 0.0027199197
A18: Staff welfare expenses | B18: 289262 | C18: =B18/B6 -> 0.00087932873 | D18: 59275 | E18: =D18/D6 -> 0.00022905929 | F18: =B18-D18 -> 229987 | G18: =E18-C18 -> -0.00065026944
A19: Administrative and other expenses | B19: 18130831 | C19: =B19/B6 -> 0.055115986 | D19: 16158934 | E19: =D19/D6 -> 0.06244376 | F19: =B19-D19 -> 1971897 | G19: =E19-C19 -> 0.0073277736
A20: Change in inventory | B20: 11025000 | C20: =B20/B6 -> 0.033514942 | D20: -18800000 | E20: =D20/D6 -> -0.072649762 | F20: =B20-D20 -> 29825000 | G20: =E20-C20 -> -0.1061647
A21: CSR Fund | B21: 2860000 | C21: =B21/B6 -> 0.0086941257 | D21: 873749.9 | F21: =B21-D21 -> 1986250.1 | G21: =E21-C21 -> -0.0086941257
A22: Depreciation | B22: 3467812 | C22: =B22/B6 -> 0.010541816 | D22: 3900665.2 | E22: =D22/D6 -> 0.015073532 | F22: =B22-D22 -> -432853.2 | G22: =E22-C22 -> 0.004531716
F23: =SUM(F11:F22) -> 41220518
A24: Profit 2019-20 | B24: 52056151 | C24: =B24/B6 -> 0.15824571
A25: Profit 2020-21 | B25: 18639394 | C25: =B25/D6 -> 0.072029126
A27: Decrease in Profit | B27: =B25-B24 -> -33416757
A30: Efficiency variance
A32: Particulars | B32: Percentage on Sales on 2019-20 | C32: Expected | D32: Actual | E32: Variance from Expected
A35: Sales for the period 2020 to 2021 | B35: =D6 -> 2.587758e+08 | D35: =B35 -> 2.587758e+08
A37: CONSTRUCTION AND OPERATING
A38: Construction Material Consumed | B38: =C11 -> 0.21258342 | C38: =$D$35*B38 -> 55011445 | D38: =D11 -> 81386421 | E38: =C38-D38 -> -26374977
A39: Wages paid | B39: =C12 -> 0.31171705 | C39: =$D$35*B39 -> 80664828 | D39: =D12 -> 95817327 | E39: =C39-D39 -> -15152499
A40: Construction Work Expenses | B40: =C13 -> 0.12658594 | C40: =$D$35*B40 -> 32757377 | D40: =D13 -> 32380431 | E40: =C40-D40 -> 376945.55
A41: EMPLOYEE BENEFITS EXPENSE | B41: =C14 -> 0 | D41: =D14 -> 0
A42: Salaries and wages | B42: =C15 -> 0.089706016 | C42: =$D$35*B42 -> 23213746 | D42: =D15 -> 27106724 | E42: =C42-D42 -> -3892978.3
A43: Contribution to Provident and other funds | B43: =C16 -> 0.014070558 | C43: =$D$35*B43 -> 3641119.8 | D43: =D16 -> 4023696 | E43: =C43-D43 -> -382576.21
A44: Director’s Remuneration | B44: =C17 -> 0.011490837 | C44: =$D$35*B44 -> 2973550.6 | D44: =D17 -> 3677400 | E44: =C44-D44 -> -703849.4
A45: Staff welfare expenses | B45: =C18 -> 0.00087932873 | C45: =$D$35*B45 -> 227548.99 | D45: =D18 -> 59275 | E45: =C45-D45 -> 168273.99
A46: Administrative and other expenses | B46: =C19 -> 0.055115986 | C46: =$D$35*B46 -> 14262683 | D46: =D19 -> 16158934 | E46: =C46-D46 -> -1896250.4
A47: Change in inventory | B47: =C20 -> 0.033514942 | C47: =$D$35*B47 -> 8672855.9 | D47: =D20 -> -18800000 | E47: =C47-D47 -> 27472856
A48: CSR Fund | B48: =C21 -> 0.0086941257 | C48: =$D$35*B48 -> 2249829.3 | D48: 873749.9 | E48: =C48-D48 -> 1376079.4
...

Sheet WIP
A1: SATHIAPAL ENGINEERS (INDIA) LIMITED
A2: 14, Temple St., Alagappa Nagar,
A3: Kilpauk,
A4: Chennai - 600 010
A5: CIN: U74210TN2002PLC048568
A6: Cost Breakup of Ledger
A7: 1-Apr-2020 to 31-Mar-2021 | G7: WIP
B8: Ledger: Contract Receipts A/c
B9: SATHIAPAL ENGINEERS (INDIA) LIMITED - (From 1-Apr-2007) - (from 1-Apr-2012)
A10: Particulars | B10: 1-Apr-2020 to 31-Mar-2021
B11: Transactions | D11: Closing | E11: Closing in Tally | G11: contracts
B12: Debit | C12: Credit | D12: Balance | G12: purchase
A13: Primary Cost Category | G13: direct expense
A14: 21 Sugar Project | B14: 999 | C14: 0 | D14: =C14-B14 -> -999 | E14: 2288440 | G14: indirect expense
A15: CCCL.Dhachepalli Project | B15: 1306369 | C15: 2887464 | D15: =C15-B15 -> 1581095
A16: CCCL-Vizag Project | B16: 20402422 | C16: 38346998 | D16: =C16-B16 -> 17944576
A17: Coromandal Engg Co Ltd (RMC) | B17: 3540 | C17: 4278200 | D17: =C17-B17 -> 4274660
A18: Coromandal (Ramco Ariyalur) Project | B18: 1981824 | C18: 3457145 | D18: =C18-B18 -> 1475321
A19: Coromandal (Ramco) Project | B19: 63946 | C19: 669816 | D19: =C19-B19 -> 605870 | I19: fd | J19: 1084824
A20: Dalmia Cement 2020 Project | B20: 7612028 | C20: 6972946 | D20: =C20-B20 -> -639082 | J20: 638212
A21: EID Parry Karnataka Project | B21: 9309785 | C21: 9194400 | D21: =C21-B21 -> -115385 | J21: 3797980 | K21: 3856336
A22: Gujarat Ambuja Himatnagar Project | B22: 1811569 | C22: 2100000 | D22: =C22-B22 -> 288431 | J22: =J19+J20+J21 -> 5521016 | K22: =J19+J20+K21 -> 5579372
A23: Hotel Sadhabishgam Project | C23: 127118 | D23: 127118
A24: ITC Bhadrachalam Telangana 2019 Project | B24: 31197721 | C24: 30302188 | D24: =C24-B24 -> -895533
A25: KEC Project (Chimney) Jharkhand | B25: 10079786 | C25: 10460923 | D25: =C25-B25 -> 381137 | J25: =K22-J22 -> 58356
A26: Mela Gurumuhurtham Project | B26: 240000 | C26: 6000000 | D26: =C26-B26 -> 5760000
A27: MRN Cane Power II Project - Karnataka | B27: 2779311 | C27: 1452882 | D27: =C27-B27 -> -1326429 | G27: =D24+D27+D28+D34+D35+D37+D39+D20+D21+D14 -> -17581760
A28: Nirma Project | B28: 14377479 | C28: 7828408 | D28: =C28-B28 -> -6549071
A29: Novoco Project | B29: 1595944 | C29: 2658875 | D29: =C29-B29 -> 1062931
A30: Nuvoco Jojobera Cement Jharkhand Project | B30: 8709756 | C30: 11032518 | D30: =C30-B30 -> 2322762
A31: Philips Carban Project | B31: 6005878 | C31: 12209897 | D31: =C31-B31 -> 6204019
A32: Ramco Cement R R Nagar Project | B32: 28153750 | C32: 30465628 | D32: =C32-B32 -> 2311877.9
A33: RSK Kaliyaraj Project | B33: 0.36 | C33: 2966102 | D33: =C33-B33 -> 2966101.6
A34: Rungta Mines (Chaliyama-Jharkhand) Project | B34: 9371874 | C34: 6595887 | D34: =C34-B34 -> -2775987
A35: Rungta Mines (Kamanda-Odisha) Project | B35: 8231261 | C35: 6611838 | D35: =C35-B35 -> -1619423
A36: Sanghi Industries CPP Chimney Project | B36: 34045 | C36: 2142212 | D36: =C36-B36 -> 2108167
A37: Sanghi Industries II Project | B37: 3712881 | C37: 1329081 | D37: =C37-B37 -> -2383800
A38: Satguru Cement Pvt Ltd | B38: 19623428 | C38: 28562740 | D38: =C38-B38 -> 8939312
A39: Sayaji Industries Ltd Project | B39: 4627201 | C39: 3351150 | D39: =C39-B39 -> -1276051
A40: SRR Projects Pvt Ltd Project | C40: 62345 | D40: =C40-B40 -> 62345
...

Sheet IT
B2: Assessee's Name | C2: M/s. Sathiapal Engineers (India) Private Limited (Formerly known as M/S Sathiapal Engineers (India) Limited) | D2: Status | E2: Private Limited Company
C3: =BS!A3 -> CIN: U74210TN2002PLC048568
B4: Date of Incorporation | C4: 07.03.2002 | D4: PAN | E4: AAHCS2295P | W4: AMOUNT DUE | Y4: =ROUND(+#REF!,-2) -> #REF!
B5: Nature of Business | C5: Engineering & Construction | D5: I.T.Juri | E5: CO.RANGE VI(1) | T5: DUE DATE | V5: PAID | W5: AMOUNT | Y5: CHARGED
B6: Address: Registered Office: | C6: New No. 57, Old No. 3, Canal Road, | D6: Asst. Year | E6: 2023-24
C7: Kilpauk Garden Colony, Kilpauk, Chennai 600 010. | D7: Year Ending | E7: 31.03.2023 | T7: 15.09.2005 | U7: 0 | V7: 0 | W7: =+#REF!+V7 -> #REF! | X7: =+#REF!-W7 -> #REF! | Y7: =ROUND(X7*1%*3,0) -> #REF!
B9: STATEMENT OF TOTAL INCOME ( in '000s)
B10: INCOME FROM BUSINESS
B11: Net Profit as per Profit & Loss A/c. | E11: =+PL!C35 -> 46240223 | T11: 15.03.2006 | U11: 0 | V11: 0 | W11: =+#REF!+V11 -> #REF! | X11: =+#REF!-W11 -> #REF! | Y11: =ROUND(X11*1%*1,0) -> #REF!
B12: LESS: INCOME CONSIDERED SEPARATELY
B13: Interest Income | D13: =Notes!J235 -> 3323836 | E13: =+Notes!J235 -> 3323836
E14: =E11-E13 -> 42916387
B15: ADD:INADMISSIBLE EXPENSES:
B16: Depreciation as per Companies Act | D16: =Dep_Co!K26 -> 8219826.5
B17: Disallowance U/s 40A(3) | D17: =Disallowance!D14 -> 367821 | G17: 14296407
B18: Disallowance U/s 40(a)(i) | D18: =I18 -> 123600 | G18: =412000 -> 412000 | H18: =G18*30% -> 123600 | I18: =H18 -> 123600
B19: Disallowance U/s 36(1)(va) | D19: 0 | F19: 382438
B20: Disallowance U/s 37(i) | D20: =H23 -> 125012.94 | F20: Penalty | H20: 125382.94
B21: Capital Expenditure | D21: 0
B22: Donation | D22: =261950 -> 261950 | E22: =SUM(D16:D22) -> 9098210.4 | F22: =Notes!J281-100000 -> 161950 | G22: 261950 | H22: =185*2 -> 370
H23: =H20-H22 -> 125012.94
E26: =E14+E22 -> 52014597 | G26: 100000 | W26: Total | Y26: =SUM(Y6:Y16) -> #REF!
B27: LESS: ADMISSIBLE EXPENSES
B28: Depreciation as per Income Tax Act | D28: =Dep_IT!I23 -> 11820033 | E28: =D28 -> 11820033
B29: Donation | D29: =G26*50% -> 50000 | E29: =D29 -> 50000
E30: =E26+E29-E28 -> 40244564
B31: INCOME FROM OTHER SOURCES:
B32: Interest Income | D32: =D13 -> 3323836 | E32: =D32 -> 3323836
B35: GROSS TOTAL INCOME
B36: Income from Business | E36: =E30 -> 40244564
B37: Income from other sources | E37: =E32 -> 3323836
E38: =SUM(E36:E37) -> 43568400
E39: or
C40: TOTAL INCOME (as rounded off) | E40: =E38 -> 43568400
B41: STATEMENT OF TAXES
B42: I . Tax on Total Income @ 22% u/s 115 BAA | E42: =E40*0.22 -> 9585048.1
B43: Add: Surcharge @ 10% on above | E43: =E42*10% -> 958504.81
E44: =E42+E43 -> 10543553
B45: Add: Education cess @ 4% on above | E45: =E44*4% -> 421742.12
E46: =+E44+E45 -> 10965295
...

Sheet Disallowance
B3: Si.no | C3: Particulars | D3: Amount
B4: 1 | C4: Benz car service | D4: 28633
B5: =B4+1 -> 2 | C5: Marriage Gift to Mr. velappan | D5: 30600
B6: =B5+1 -> 3 | C6: Sillvan Gift | D6: 10490
B7: =B6+1 -> 4 | C7: Angusamy gst notice purpose | E7: 44977 | F7: GST - AMOUNT PAID TO COMMISSIONER
B8: =B7+1 -> 5 | C8: Wagnor Car service | D8: 20157
B9: =B8+1 -> 6 | C9: Skoda car serivce | D9: 61383
B10: =B9+1 -> 7 | C10: Benz car service | D10: 12558
B11: 8 | C11: Audit fees
D12: =SUM(D4:D10) -> 163821
C13: Godown rent | D13: 204000
D14: =D12+D13 -> 367821

Sheet policies old
A2: =+BS!A2 -> M/s. Sathiapal Engineers (India) Private Limited (Formerly known as M/S Sathiapal Engineers (India) Limited)
A3: =+BS!A4 -> New No. 57, Old No. 3, Canal Road, Kilpauk Garden Colony, Kilpauk, Chennai 600 010.
A4: Notes forming part of the financial statements
A6: Ref No. | B6: Note | C6: Particulars
B8: 1 | C8: Corporate information
C9: M/s. Sathiapal Engineers (India) Private Limited formerly known as M/s. Sathiapal Engineers (India) Limitedis registered with the Chennai Registrar of Companies as a Public Limited Company on 07th March 2002 vide Registration no. U74210TN2002PLCO48568
C11: .
C12: The registered office of the company is located at New No.14, Old No.25, Temple Street, Alagappa Nagar, Kilpauk, Chennai - 600 010.
C14: The Principal activities of the Company is to engage in microfinance activities with the ultimate objective of benefiting the poor and downtrodden, (organized in the form of Self Help Groups) for enhancement of their livelihoods in a financially viable manner. The Company generally provides small value collateral free loans upto Rs. 1,00,000 for a tenor of 20 months with monthly repayment.
C15: The Principal activities of the Company is undertaking Specialised Construction of Tall Structures like Silos for Cement Plants, RCC Chimneys for Power, Suger, Paper, Chemical, etc., thro Slip-Form Technology and also Construction of Educational Institutions.
C16: The Company was converted from Public Company to Private company with effect from 10th April 2019 and herein after called as M/s.Sathiapal Engineers (India) Private limited.
A18: AS 1.1 | B18: 2 | C18: Significant accounting policies
A19: i | C19: The significant accounting policies have been predominantly presented below in the order of the Accounting Standards notified under the Companies (Accounting Standards) Rules, 2006 (as amended). The order of presentation may be customised for each Company.
A20: i | C20: The significant accounting policies would need to be customised for each Company based on its applicability and relevance. For example, in case of a Small and Medium Sized Company, it should state in its financial statements that "The Company is a Small and Medium Sized Company as defined in the General Instructions in respect of Accounting Standards notified under the Companies (Accounting Standards) Rules, 2006 (as amended). Accordingly, the Company has complied with the Accounting Standards as applicable to a Small and Medium Sized Company." and should also modify the accounting policies suitably. Similarly, companies that have not opted for the transition provisions in para 46 / 46A of AS 11 The Effects of Changes in Foreign Exchange Rates and companies that have not opted for Hedge Accounting should modify the accounting policies on Foreign Currency Transactions and Translations and Hedge Accounting, respectively.
B21: 2.1 | C21: Basis of accounting and preparation of financial statements
C23: The financial statements of the Company have been prepared in accordance with the Generally Accepted Accounting Principles in India (Indian GAAP). The Company has prepared these financials statements to comply in all material respects with the Accounting Standards notified under the Companies (Accounting Standards) Rules, 2014 (as amended) and the relevant provisions of the Companies Act, 2013. The financial statements have been prepared on accrual basis and the directions issued by the Reserve Bank of India to the extent applicable to the Company.
B25: =B21+0.1 -> 2.2 | C25: Use of estimates
C27: The preparation of the financial statements in conformity with Indian GAAP and that requires the Management to make estimates and assumptions that affect the reported amounts of assets and liabilities and disclosure of contingent assets and liabilities at the date of the financial statements and reported amounts of revenues and expenses during the reporting period. Although such estimates are made on a reasonable and prudent basis taking into account all available information, actual results could differ from those estimates.
A29: AS 2.26.a | B29: =B25+0.1 -> 2.3 | C29: Inventories
C31: Inventories are valued at cost (on FIFO ) and providing for obsolescence and other losses, where considered necessary. Cost of raw materials, Packing materials, Stores, Spares and Consumables includes all charges in bringing the goods to the point of sale, including octroi and other levies, transit insurance and receiving charges.
A34: =$A$2 -> M/s. Sathiapal Engineers (India) Private Limited (Formerly known as M/S Sathiapal Engineers (India) Limited)
A35: =$A$3 -> New No. 57, Old No. 3, Canal Road, Kilpauk Garden Colony, Kilpauk, Chennai 600 010.
A36: =$A$4 -> Notes forming part of the financial statements | B36: Notes forming part of the financial statements
B38: Note 2 Significant accounting policies (contd.)
A40: Ref No. | B40: Note | C40: Particulars
B43: =B29+0.1 -> 2.4 | C43: Cash and cash equivalents (for purposes of Cash Flow Statement)
A45: AS 3.5.2 | C45: Cash comprises cash on hand and demand deposits with banks. Cash equivalents are short-term balances (with an original maturity of three months or less from the date of acquisition), highly liquid investments that are readily convertible into known amounts of cash and which are subject to insignificant risk of changes in value.
B47: =B43+0.1 -> 2.5 | C47: Cash flow statement
C49: Cash flows are prepared in accordance with the indirect method prescribed in Accounting Standard-3.
B51: =B47+0.1 -> 2.6 | C51: Fixed Assets
C53: Fixed assets are stated at cost net of depreciation. The cost of an asset comprises its purchase price and any cost directly attributable for bringing the asset to its working condition and location for its intended use.
B55: =B51+0.1 -> 2.7 | C55: Depreciation
A57: AS 6.29 AS 26.63 AS 26.78 AS 26.90.a AS 26.90.b AS 26.94.a | C57: Depreciable amount for assets is the cost of an asset, or other amount substituted for cost, less its estimated residual value. Depreciation on tangible fixed assets has been provided on Straight Line value method as per the useful life prescribed in Schedule II to the Companies Act, 2013.
C58: Depreciation on additions is charged proportionately from the date of acquisition/installation.
C59: Individual assets costing less than Rs. 5000/- are depreciated in ful, in the year of acquisition.
B70: =B55+0.1 -> 2.8 | C70: Receivables
C72: Receivables under Financing activity include Gold Loans, Mortgage Loans and Business Loans. Loans are classified into 'Performing and Non-Performing' assets in terms of the Non Banking Financial Companies Prudential Norms (Reserve Bank) Directions, 1998 issued by the Reserve Bank of India as amended from time to time.
B74: =B55+0.1 -> 2.8 | C74: Revenue recognition
C76: Revenues from Interest on loans financed by the company is recognized on accrual basis, considering the directions issued by the Reserve Bank of India from time to time in terms of the Non Banking Financial Companies Prudential Norms (Reserve Bank) Directions, 1998. Loans are classified into 'Performing and Non-Performing' assets in terms of the said Directions.
C77: Revenues from loan documentation and meeting charges are recognised as income on cash basis.
...

Sheet Cash Flow
B2: =+PL!A2 -> M/s. Sathiapal Engineers (India) Private Limited (Formerly known as M/S Sathiapal Engineers (India) Limited)
C3: =BS!A3 -> CIN: U74210TN2002PLC048568
B4: =+PL!A4 -> New No. 57, Old No. 3, Canal Road, Kilpauk Garden Colony, Kilpauk, Chennai 600 010.
B6: CASH FLOW STATEMENT FOR THE YEAR ENDED 31ST MARCH, 2023
D7: (Rs.in 000's)
B8: Particulars | D8: For the year 2022-23 | F8: For the year 2021-22
D9: ₹ | E9: ₹ | F9: ₹ | G9: ₹ | I9: =D13/1000 -> 8219.8265
B10: A. Cash flow from operating activities
B11: Net Profit / (Loss) before extraordinary items and tax | E11: =+PL!C30 -> 43618707 | G11: =30083.6078004535*1000 -> 30083608 | H11: 1000
B12: Adjustments for: | H12: =D116 -> -5360596
B13: Depreciation and amortisation | D13: =Dep_Co!K26 -> 8219826.5 | F13: =9718.98258954644*1000 -> 9718982.6
B14: Interest | D14: =-Notes!J235 -> -3323836 | F14: =-4642.716*1000 -> -4642716
B15: Dividend
B16: Rent
B17: Amortisation of share issue expenses and discount on shares
B18: (Profit) / loss on sale of assets | D18: =(-'Audit entries FY 22-23'!D71) -> -216704 | H18: 1000
B19: Write off of assets | D19: =Dep_Co!H13 -> 868251
B20: Finance costs
B21: Interest income
B22: Prior period Adjustment | D22: =PL!C31 -> 2621516 | I22: =#REF!-#REF! -> #REF!
E23: =SUM(D13:D22) -> 8169053.5 | G23: =5076.26658954644*1000 -> 5076266.6
B24: Operating profit / (loss) before working capital changes | E24: =SUM(E11:E23) -> 51787761 | G24: =SUM(G11:G23) -> 35159874
B25: Changes in working capital:
B26: Adjustments for (increase) / decrease in operating assets:
B27: Inventories | D27: =+BS!E46-BS!C46 -> -51490000 | F27: 4160000
B28: Trade Receivables | D28: =+BS!E47-BS!C47 -> 47643265 | F28: 1872245.2
B29: Short-term loans and advances | D29: =BS!E49-BS!C49 -> -35103265 | F29: -6339202.2
B30: Long-term loans and advances | D30: =BS!E41-BS!C41 -> 1660362.8 | F30: 0
B31: Other current assets | D31: =BS!E50-BS!C50-BS!C40 -> 3935754 | F31: -719070
F32: 0 | J32: 27.10.2021
B33: Adjustments for increase / (decrease) in operating liabilities: | F33: 0
B34: Trade payables | D34: =BS!C25-BS!E25 -> 11210090 | F34: -7769310.4
B35: Other current liabilities | D35: =BS!C26-BS!E26 -> -18558220 | F35: 14132294
B36: Other long-term liabilities | F36: 0
B37: Short-term provisions | D37: 0 | F37: 0
B38: Short term borrowings | D38: =BS!C24-BS!E24+5 -> 8351507 | F38: -1431555
E39: =SUM(D27:D38) -> -32350507 | G39: =3905.40118084745*1000 -> 3905401.2
E40: =SUM(E24:E39) -> 19437253 | G40: =39065.2755708474*1000 -> 39065276
B41: Cash flow from extraordinary items | E41: 0 | G41: 0
B42: Cash generated from operations | E42: =E40-E41 -> 19437253 | G42: =G40-G41 -> 39065276
...

Sheet Audit entries FY 22-23
A1: S.No | B1: Particulars | C1: Dr | D1: Cr
A2: 1 | B2: Audit Fees | C2: 412000
B3: TDS Payable | C3: =C2*10% -> 41200
B4: A john moris & Co | D4: =C2-C3 -> 370800
B5: (Audit fees for the FY 22-23)
A7: 2 | B7: Interest on PF | C7: =718+125+13866 -> 14709
B8: To PF (Site) | D8: =C7 -> 14709
B9: (Interest on PF for delayed payment)
A12: =A7+1 -> 3 | B12: Princy land surveyors | C12: 18149.153
B13: Smart Exteriors | C13: 16200
B14: Sri Amman Lath works | C14: 11393.76 | E14: Trade payable
B15: BBR (India) pvt ltd | C15: 931.89576
B16: Shri Vishnu Refractories | C16: 5672.4305 | E16: Trade payable
B17: Steel Link | C17: 1913.5466 | E17: Trade advances
B18: Steel world | C18: 1006.4907 | E18: Trade payable
B19: Ajay Singh | C19: 5481.84 | E19: Trade advances
B20: Borana Engineers & Contractors | C20: 4240 | E20: Trade payable
B21: Elite Engineers | C21: 5959
B22: Gulam Nabi & Sons | C22: 62460
B23: Jai Biswas | C23: 14457.74
B24: Jitendra Kumar Carpentor | C24: 12616.11 | E24: Trade payable
B25: Mohammad Shahensha | C25: 534.43 | E25: Trade advances
B26: Narendhar Saw | C26: 8140.26
B27: Ram Sagar Singh | C27: 1992.17 | E27: Trade payable
B28: R.J. Enterprises | C28: 13996.322
B29: Sadanandakar | C29: 1606
B30: S.K. Steel | C30: 4333.6102 | E30: Trade payable
B31: Sushmaa Demolition work | C31: 851.54237 | E31: Trade payable
B32: Aarov Readymix | C32: 1077.6271
B33: Navkar Construction Company | C33: 2740.4576 | E33: Trade payable
B34: Sri Venkata Padmaja Ceramics | C34: 1682.3695 | E34: Trade advances
B35: To TDS Payable | D35: =SUM(C12:C34) -> 197436.75
A37: =A12+1 -> 4 | B37: TCS Receivable | C37: =SUM(D38:D40) -> 172218
B38: To Steel | D38: 10518 | E38: construction material consumed
B39: To RMC | D39: 22284 | E39: construction material consumed
B40: To planks runners & plywood | D40: 139416 | E40: construction material consumed
A42: =A37+1 -> 5 | B42: TDS Receivable
B43: To Contract advance | D43: =C42 -> 0
A45: 6 | B45: Staff welfare expenses | C45: 231886.25
B46: To ESI | D46: 231886.25
...

Sheet BS
A2: =IT!C2 -> M/s. Sathiapal Engineers (India) Private Limited (Formerly known as M/S Sathiapal Engineers (India) Limited)
A3: CIN: U74210TN2002PLC048568
A4: New No. 57, Old No. 3, Canal Road, Kilpauk Garden Colony, Kilpauk, Chennai 600 010.
A6: Balance Sheet as at 31st March 2023 as per schedule III of Companies Act 2013
A8: Particulars | B8: Notes | C8: As at 31.03.2023 | E8: As at 31.03.2022 | G8: As at 31.03.2019
G9: =PL!D9 -> 0
A10: I.EQUITY AND LIABILITIES
A12: (1)SHAREHOLDER'S FUND | J12: =1/1000 -> 0.001
A13: (a)Share Capital | B13: =Notes!B7 -> 3 | C13: =Notes!I16 -> 7147460 | E13: =7147.46*1000 -> 7147460 | G13: =Notes!K16 -> 7147460 | J13: =D15*1000 -> 3.2270884e+11
A14: (b)Reserves and Surplus | B14: =Notes!B41 -> 4 | C14: =+Notes!J59 -> 3.1556138e+08 | E14: =286389.161555591*1000 -> 2.8638916e+08 | G14: =Notes!#REF! -> #REF!
D15: =+C13+C14-0.3 -> 3.2270884e+08 | F15: =+E13+E14 -> 2.9353662e+08 | H15: =SUM(G13:G14) -> #REF! | I15: =D15-F15 -> 29172221 | J15: ='Cash Flow'!E11 -> 43618707 | K15: =J15-I15 -> 14446486 | L15: =PL!C34 -> 0 | M15: =K15-L15 -> 14446486
A16: (c)) Money received against share warrants
A17: (2)SHARE APPLICATION MONEY PENDING ALLOTMENT
A18: (3)NON-CURRENT LIABILITIES
A19: (a)Long Term Borrowings
A20: (b)Other long-term liabilities | B20: =+Notes!B62 -> 5 | C20: =Notes!J65 -> 32203.14 | E20: =32.20314*1000 -> 32203.14 | G20: =Notes!K65 -> 32203.14
A21: (c)Deferred Tax Liabilities | B21: =Notes!B139 -> 11 | C21: =-Notes!J156 -> 1615571.3 | E21: =-Notes!K156 -> 873452.38 | G21: =-Notes!K156 -> 873452.38 | H21: =G20+G21 -> 905655.52 | I21: =D21-F21 -> 0
A22: (c)Long term Provisions | D22: =C21+C20 -> 1647774.4 | F22: =E21+E20 -> 905655.52
A23: (4)CURRENT LIABILITIES
A24: (a)Short Term Borrowings | B24: =+Notes!B67 -> 6 | C24: =+Notes!J74 -> 11392871 | E24: =3041.369*1000 -> 3041369 | G24: =Notes!K74 -> 3041369 | I24: =C24-E24 -> 8351502 | L24: 74920
A25: (b)Trade Payables | B25: =Notes!B77 -> 7 | C25: =+Notes!J83 -> 17772800 | E25: =6562.70984*1000 -> 6562709.8 | G25: 7428819 | I25: =C25-E25 -> 11210090
A26: (c)Other Current Liabilities | B26: =Notes!B86 -> 8 | C26: =+Notes!J104 -> 22830334 | E26: =41388.55377*1000 -> 41388554 | G26: =+Notes!K104 -> 41388554 | I26: =C26-E26 -> -18558220 | L26: =SUM(L24:L25) -> 74920
A27: (d)Short Term Provisions | B27: =Notes!B107 -> 9 | C27: =+Notes!J111 -> 10965295 | E27: =8443.3364*1000 -> 8443336.4 | G27: =+Notes!K111 -> 8443336.4 | I27: =C27-E27 -> 2521958.6 | L27: 4500
D28: =+C24+C25+C26+C27 -> 62961299 | F28: =+E24+E25+E26+E27 -> 59435969 | H28: =SUM(G24:G27) -> 60302078 | L28: =SUM(L26:L27) -> 79420
A29: Total | D29: =D28+D20+D15+D22 -> 3.8731792e+08 | F29: =F28+F20+F15+F22 -> 3.5387825e+08 | H29: =SUM(H10:H28) -> #REF! | I29: =SUM(I15:I28) -> 32697551 | J29: =382773-D29 -> -3.8693514e+08 | K29: 4545.1735 | L29: 1564.472 | M29: -440 | N29: -432
A30: II.ASSETS | L30: =189563548/1000 -> 189563.55 | M30: =L30-L29 -> 187999.08 | N30: 114643 | O30: =M30-N30 -> 73356.076
A32: NON-CURRENT ASSETS | L32: =D29-D52 -> 0.68317133 | M32: =L32/2 -> 0.34158567
A33: Property,Plant & Equipment and Intangible Assets | I33: 11182296 | L33: 19277
I34: 5360596 | L34: =L33+L32 -> 19277.683 | M34: =L34 -> 19277.683
A35: (1)(a)Property,Plant and Equipments | B35: =Notes!B115 -> 10 | C35: =Dep_Co!N26 -> 79464956 | E35: =55562.0408502087*1000 -> 55562041 | H35: 45976627 | I35: -1516347 | J35: =E35-C35 -> -23902916 | K35: =C35-D15 -> -2.4324389e+08 | L35: =L32+4.2 -> 4.8831713 | M35: =L35/2 -> 2.4415857
A36: (ii)Intangible Assets | I36: 5912326
A37: (iii)Capital Work in Progress | I37: 20938871 | L37: 20938871
A38: (iv)Intangible Assets under development | K38: =E35-C35 -> -23902916 | L38: -5912326
A39: (b)Non-current Investments | C39: =+Notes!J135 -> 0 | E39: 0 | G39: =Notes!K135 -> 0 | L39: 1516347
A40: (c)Deferred Tax Assets | L40: -5360596
A41: (b)Long Term Loans and Advances | B41: =Notes!B159 -> 12 | C41: =+Notes!J165 -> 74626866 | E41: =76287.2285*1000 -> 76287228 | G41: =Notes!K165 -> 76287228
A42: (2) Deferred Tax Asset | B42: 11 | D42: =SUM(C35:C42) -> 1.5409182e+08 | F42: =E35+E41+E42 -> 1.3184927e+08 | H42: =SUM(G39:G41) -> 76287228 | I42: =F42-D42 -> -22242553
A43: (e)Other Non Current Assets
A44: (3)CURRENT ASSETS | L44: =L32*1000 -> 683.17133
A45: (a)Current Investments | L45: =L44/2 -> 341.58567
...

Sheet Corporate & Acctg Policies
A2: M/s. Sathiapal Engineers (India)Private Limited Formerly known as M/S Sathiapal Engineers (India) Limited
A3: =PL!A4 -> New No. 57, Old No. 3, Canal Road, Kilpauk Garden Colony, Kilpauk, Chennai 600 010.
A4: Notes forming part of the financial statements
A6: Note | B6: Particulars
A8: 1 | B8: Corporate information
B9: M/s. Sathiapal Engineers (India) Private Limited formerly known as M/s. Sathiapal Engineers (India) Limitedis registered with the Chennai Registrar of Companies as a Public Limited Company on 07th March 2002 vide Registration no. U74210TN2002PLCO48568
B12: The registered office of the company is located at New No. 57, Old No. 3, Canal Road, Kilpauk Garden Colony, Kilpauk, Chennai 600 010.
B14: The Principal activities of the Company is to engage in microfinance activities with the ultimate objective of benefiting the poor and downtrodden, (organized in the form of Self Help Groups) for enhancement of their livelihoods in a financially viable manner. The Company generally provides small value collateral free loans upto Rs. 1,00,000 for a tenor of 20 months with monthly repayment.
B15: The Principal activities of the Company is undertaking Specialised Construction of Tall Structures like Silos for Cement Plants, RCC Chimneys for Power, Suger, Paper, Chemical, etc., thro Slip-Form Technology and also Construction of Educational Institutions.
B16: The Company was converted from Public Company to Private company with effect from 10th April 2019 and herein after called as M/s.Sathiapal Engineers (India) Private limited.
A18: 2 | B18: Significant accounting policies
B19: The significant accounting policies have been predominantly presented below in the order of the Accounting Standards notified under the Companies (Accounting Standards) Rules, 2006 (as amended). The order of presentation may be customised for each Company.
B20: The significant accounting policies would need to be customised for each Company based on its applicability and relevance. For example, in case of a Small and Medium Sized Company, it should state in its financial statements that "The Company is a Small and Medium Sized Company as defined in the General Instructions in respect of Accounting Standards notified under the Companies (Accounting Standards) Rules, 2006 (as amended). Accordingly, the Company has complied with the Accounting Standards as applicable to a Small and Medium Sized Company." and should also modify the accounting policies suitably. Similarly, companies that have not opted for the transition provisions in para 46 / 46A of AS 11 The Effects of Changes in Foreign Exchange Rates and companies that have not opted for Hedge Accounting should modify the accounting policies on Foreign Currency Transactions and Translations and Hedge Accounting, respectively.
A21: 2.1 | B21: Basis of accounting and preparation of financial statements
B23: The financial statements of the Company have been prepared in accordance with the Generally Accepted Accounting Principles in India (Indian GAAP). The Company has prepared these financials statements to comply in all material respects with the Accounting Standards notified under the Companies (Accounting Standards) Rules, 2014 (as amended) and the relevant provisions of the Companies Act, 2013. The financial statements have been prepared on accrual basis and the directions issued by the Reserve Bank of India to the extent applicable to the Company.
A25: =A21+0.1 -> 2.2 | B25: Use of estimates
B27: The preparation of the financial statements in conformity with Indian GAAP and that requires the Management to make estimates and assumptions that affect the reported amounts of assets and liabilities and disclosure of contingent assets and liabilities at the date of the financial statements and reported amounts of revenues and expenses during the reporting period. Although such estimates are made on a reasonable and prudent basis taking into account all available information, actual results could differ from those estimates.
A33: Notes forming part of the financial statements
A35: Note 2 Significant accounting policies (contd.)
A37: Note | B37: Particulars
A40: =2.3 -> 2.3 | B40: Cash and cash equivalents (for purposes of Cash Flow Statement)
B42: Cash comprises cash on hand and demand deposits with banks. Cash equivalents are short-term balances (with an original maturity of three months or less from the date of acquisition), highly liquid investments that are readily convertible into known amounts of cash and which are subject to insignificant risk of changes in value.
A44: =A40+0.1 -> 2.4 | B44: Cash flow statement
B46: Cash flows are prepared in accordance with the indirect method prescribed in Accounting Standard-3.
A48: 2.5 | B48: Net profit or loss for the period, Prior Period items and changes in accounting policies
B50: Net profit or loss for the period, Prior Period items and changes in accounting policies have been accounted as per the Accounting Standard 5.
A52: =A48+0.1 -> 2.6 | B52: Construction Contract
B54: Inventories has been valued as per AS 7 Construction contracts on completion of the physical proportion of contract work. Expenses incurred in respect of uncompleted projects have been valued as inventories in accordance with AS 7.
A56: =A52+0.1 -> 2.7 | B56: Property plant and equipement
B58: Property plant and equipment are stated at cost net of depreciation. The cost of an asset comprises its purchase price and any cost directly attributable for bringing the asset to its working condition and location for its intended use.
B59: Depreciable amount for assets is the cost of an asset, or other amount substituted for cost, less its estimated residual value. Depreciation on Property, Plant and Equipment has been provided on Straight Line value method as per the useful life prescribed in Schedule II to the Companies Act, 2013.
B60: Depreciation on additions is charged proportionately from the date of acquisition/installation.
B63: Individual assets costing less than Rs. 5000/- are depreciated in ful, in the year of acquisition.
A74: =#REF!+0.1 -> #REF! | B74: Receivables
B76: Receivables under Financing activity include Gold Loans, Mortgage Loans and Business Loans. Loans are classified into 'Performing and Non-Performing' assets in terms of the Non Banking Financial Companies Prudential Norms (Reserve Bank) Directions, 1998 issued by the Reserve Bank of India as amended from time to time.
A78: 2.8 | B78: Revenue recognition
B80: Revenues from Interest on loans financed by the company is recognized on accrual basis, considering the directions issued by the Reserve Bank of India from time to time in terms of the Non Banking Financial Companies Prudential Norms (Reserve Bank) Directions, 1998. Loans are classified into 'Performing and Non-Performing' assets in terms of the said Directions.
B81: Revenues from loan documentation and meeting charges are recognised as income on cash basis.
B82: Revenue is recognized to the extent that it is probable that the economic benefits will flow to the Company and the revenue can be reliably measured.
B83: Sale of goods
...

Sheet Sheet5

Sheet bS TALLY
A1: SEIL 12TO19
A2: Balance Sheet
A3: 1-Apr-2020 to 31-Mar-2021
B4: SEIL 12TO19 | E4: SEIL 12TO19
A5: Liabilities | B5: as at 31-Mar-2021 | D5: Assets | E5: as at 31-Mar-2021
A6: Capital Account | C6: 7147460 | D6: Fixed Assets | F6: 54365518
A7: SHARE CAPITAL | B7: 7147460 | D7: BUILDINGS | E7: 868251
A8: Loans (Liability) | D8: Camera
A9: Current Liabilities | C9: 17134887 | D9: COMPUTER | E9: 882128.8
A10: Crs. for Other Liabilities | D10: FURNITURE AND FITTINGS | E10: 34086.35
A11: Service Tax Payable | D11: LAND
A12: STAFF DEPOSIT | D12: Plant & Machinery | E12: 48499895 | I12: =F6-Dep_Co!K26 -> 46145692
A13: Sundry Creditors | B13: 16729475 | D13: Vehicle | E13: 4081157.5
A14: Crs. for I.T | D14: Current Assets | F14: 95381639
A15: Apex Topomappers Pvt Ltd | D15: Closing Stock
A16: Audit Fees Payable | D16: Deposits (Asset)
A17: Dividend Payable | D17: Loans & Advances (Asset) | E17: 22168775
A18: Dividend Tax Payable | D18: Sundry Debtors | E18: 58880461
A19: Lakhdata SD | B19: 78862 | D19: Cash-in-hand | E19: 203185.75
A20: Loyyal Battery Service | D20: Bank Accounts | E20: 6855741.8
A21: Provision for Income Tax -II | D21: Interest Receivable | E21: 7273476
A22: SECURITY DEPOSIT | B22: 294347 | D22: Vijay Gowtham Mob.Adv
A23: Vijay Gowtham SD | B23: 32203.14 | D23: Branch / Divisions | F23: 7983555.9
A24: CONTRACT ADVANCE | C24: 10969671 | D24: 21 Sugar Site
A25: CHAITANESWAR SSK - CA | B25: 30000 | D25: Aarthi Indusries II Site
A26: CHITTOOR CO-OP C.ADV | B26: 230500 | D26: Aarthi Industries Site
A27: Contract Advance | B27: 10589171 | D27: ABG Site
A28: MRUDAGIRI SSK LTD C.ADV | B28: 120000 | D28: Abhijeet III Site
A29: DEFERRED TAX LIABILITY C.L | C29: 1517336.2 | D29: Abhijeet II Site | E29: -201
A30: DEFERRED TAX LIABILITY C.L | B30: 1517336.2 | D30: Abhijeet IV SITE
A31: DIRECTORS LOAN A/C | C31: 4389286 | D31: Abhijeet Site
A32: Kumaran.S Dir - Loan | B32: 4431105 | D32: Acon (Lokmaniya Sugar) Site | E32: -34050
A33: Niranjan - S.Holder | D33: Ala Dandapani Cement II Site | E33: -1544
A34: RAJATHILAGAM.S Dir.Loan | D34: Ala Dandapani Cement Site
A35: Ramalingam.V Dr. S.H | D35: Alagu Jothi Arch Work Site
A36: SATHIAPAL.S. D. LOAN | D36: Alagu Jothi Existing Work Site
A37: Sugunthakumari.R - S.Holder | D37: Alagu Jothi Foot Path Site | E37: -2
A38: Suhashini K -Dir Loan | B38: -4127 | D38: Alagu Jothi II Site
A39: Visalakshi .K- Dir Loan | B39: -37692 | D39: Ambuja Cement Site
A40: GST | C40: 7512923 | D40: Amirthakadeswarar Gurukkal Site
...

Sheet PL TALLY
A1: SEIL 12TO19
A2: Profit & Loss A/c
A3: 1-Apr-2020 to 31-Mar-2021
B4: SEIL 12TO19 | E4: SEIL 12TO19
A5: Particulars | B5: 1-Apr-2020 to 31-Mar-2021 | D5: Particulars | E5: 1-Apr-2020 to 31-Mar-2021
A6: Purchase Accounts | C6: 81386421 | D6: Contracts | F6: 2.5646036e+08
A7: 10 MM CHIPS | B7: 963570 | D7: CONTRACT RECEIPTS
A8: 10 MM METAL | B8: 1850 | D8: Contract Receipts A/c | E8: 2.5646036e+08
A9: Asbestos Materials | B9: 777374 | D9: RMC Sales
A10: Aviation Lamp and Accessories | B10: 2012050 | D10: WIP | F10: 13800000
A11: BOLTS & NUTS | B11: 724656 | D11: WIP | E11: 13800000
A12: C.I CAP | B12: 1658846 | E12: 2.7026036e+08
A13: FIRE BRICKS | B13: 8355016 | D13: Gross Profit b/f | F13: 60277837
A14: G.I Materials | B14: 961150 | D14: Indirect Incomes | F14: 5656621
A15: Purchase | B15: -17000000 | D15: Divdend
A16: R.R. Stone | D16: Dividend
A17: Safety Materials | B17: 1702563.1 | D17: INTEREST RECEIVED on FD | E17: 5656621
A18: Soling Stone | D18: Misc.Income
A19: SS CONE | B19: 158686 | D19: Other Income
A20: Store Materials | D20: Rent Received
A21: Water for Construction
A22: Water for Contruction
A23: 12 MM Metal | B23: 1103189
A24: 20 MM METAL | B24: 3885646
A25: 40 MM METAL | B25: 45800
A26: 6 mm Metal | B26: 31385
A27: Binding Wire | B27: 831045
A28: BRICKS | B28: 625168
A29: CEMENT | B29: 5856138
A30: Consumables | B30: 4499387.9
A31: Electrical Materials | B31: 2677466.4
A32: Misc Materials | B32: 4390
A33: Painting Materials | B33: 3733599.7
A34: Petrol Diesel & Grease | B34: 363941.3
... A43: Windows & Doors | B43: 444871
A44: Direct Expenses | C44: 1.285961e+08
A45: WAGES | B45: 96190536
A46: WORKS EXPENSES | B46: 32405569
A47: Gross Profit c/o | C47: 60277837
B48: 2.7026036e+08
...

Sheet TDS
A1: 194A | B1: =57686+63576+495539 -> 616801
A2: 194C | B2: =190527+37558+26000+25100+30560+156888+286644+1127939+33333+262987+166405+119680+225000+223860+215957+107525+82531+188700+52100+1973805.63 -> 5533099.6 | D2: AVC COLLEGE OF ENGINEERING
A3: 194IA | B3: =50749 -> 50749
B4: =SUM(B1:B3) -> 6200649.6 | C4: 6236242.6 | D4: =B4-C4 -> -35593 | E4: 6219807.6 | F4: =B4-E4 -> -19158 | H4: ICICI KILPAUK | I4: 140064.47
A5: ADVANCE TAX | B5: =1248000+832000+1101885+260000+1040000+572000+1040000+824000 -> 6917885 | H5: KELLYS I | I5: 24337.5
A6: SRR PROJECTS | H6: KELLYS II | I6: CLOSED | L6: gross
A7: TALLY | B7: 26AS | C7: DIFF | H7: SBI KILPAUK I | I7: 13975118 | J7: 26Q | K7: Q1 | L7: 902151 | M7: 182202 | N7: 24Q | O7: 184935
A8: =25463+53300+31182+12083+5475 -> 127503 | B8: 50749 | C8: =A8-B8 -> 76754 | H8: SBI KILPAUK II | I8: 2540565.2 | J8: 26Q | K8: Q2 | L8: 1123085 | M8: 47084
A9: HAJEE AP BAVA INFRA | H9: SBI KILPAUK III | I9: 2885227.5 | K9: Q3
A10: =25873+116137+7260+7751+7751+25755 -> 190527 | B10: =25873+116137+7751+7751+7260+25755 -> 190527
A11: MRN CANE POWER
A12: =13500+13500+6372+1000+3186 -> 37558 | B12: =1000+9558+27000 -> 37558
A13: SRI MARUTHI POWER GEN
A14: =20000+6000 -> 26000 | B14: =6000+20000 -> 26000
A15: ARTHI INDUSTRIES LIMITED
A16: =25100 -> 25100 | B16: =25100 -> 25100
A17: DEEPAK PHENOLICS
A18: 30560 | B18: =30560 -> 30560
A19: AVC COLLEGE OF ENGG
A20: =78706+16678+9856+8475+19830+6780+10169+20339+20102+9949+20339+19932+821+20339+820+20339+8475+28814+821+20000+24000 -> 365584 | B20: =78706+42289+10529+25364+286644 -> 443532 | C20: =A20-B20 -> -77948
A21: CHETTINAD CEMENT
A22: =107110+98111+47349+78318+93679+20980+11128+286350+91594+136037+78716+78567 -> 1127939 | B22: =107110+78567+98111+11128+47349+171997+20980+286350+78716+91594+136037 -> 1127939 | C22: =A22-B22 -> 0
A23: R VENKATESH
A24: =9217+7674+8816+7626 -> 33333 | B24: =9217+7674+8816+3626+4000 -> 33333
A25: COROMANDEL ENGINEERING
A26: =47657+33974+29755+77976+47919+25706 -> 262987 | B26: =262987 -> 262987
A27: JINDAL URBAN
A28: =80086+38750+23236+24333 -> 166405 | B28: =166405 -> 166405
A29: GODAVARI POLYMERS
A30: =29920+29920+59840 -> 119680 | B30: =119680 -> 119680
A31: SAGAR CEMENTS
A32: =37500+25000+25000+25000+12500+12500+12500+12500+12500+12500+37500 -> 225000 | B32: =225000 -> 225000 | C32: =B32-A32 -> 0
A33: INDIA CEMENTS
A34: =73860+150000 -> 223860 | B34: =223860 -> 223860
A35: GOEL
A36: =43259+30000+15129+31692+43991+15144+20643+16099 -> 215957 | B36: =215957 -> 215957
A37: ATC TYRES
A38: =12650+12650+25300+25300+31625 -> 107525 | B38: 107525
A39: RAY ENGG
A40: =30786+32345+19400 -> 82531 | B40: 82531
...

Sheet consolidated tb 18-19
A1: Trial Balance
B2: Debit | C2: Credit | D2: Debit | E2: Credit
A3: Capital Account | E3: 7147460
A4: Share Capital | E4: 7147460
A5: Current Liabilities | B5: 737524 | C5: 2055676.5 | D5: 9078788.5 | E5: 11063897
A6: Sundry Creditors | B6: 737524 | C6: 2055676.5 | D6: 4825462.5 | E6: 10658485 | F6: =E6+C6-D6-B6 -> 7151174.6
A7: Crs.for Expenses | C7: 162950 | D7: 1125045 | E7: 4555540.9 | F7: =E7+C7-D7 -> 3593445.9
A8: A John Moris & Co | E8: 938288.93 | F8: =B8+C8+D8+E8 -> 938288.93 | G8: cr
A9: Aurobindo Business Machines | E9: 12154 | F9: =B9+C9+D9+E9 -> 12154 | G9: cr
A10: BUSINESS ACCOUNTING SOLUTION | E10: 8000 | F10: =B10+C10+D10+E10 -> 8000 | G10: cr
A11: HARIPRASAD ASSOCIATES | D11: 500045 | F11: =B11+C11+D11+E11 -> 500045 | G11: dr
A12: Janu Engg Works | C12: 144197 | F12: =B12+C12+D12+E12 -> 144197 | G12: cr
A13: J.S.Metal Graft (Jeevanatham) | C13: 3845 | F13: =B13+C13+D13+E13 -> 3845 | G13: dr
A14: KB Mehta Construction Pvt Ltd | D14: 100000 | F14: =B14+C14+D14+E14 -> 100000 | G14: dr
A15: Mesha | E15: 21700 | F15: =B15+C15+D15+E15 -> 21700 | G15: cr
A16: N.K.BHANSALI & CO | D16: 525000 | F16: =B16+C16+D16+E16 -> 525000 | G16: dr | H16: =39821-14815-14820 -> 10186
A17: OUTSTANDING DIRECTORS REMUNERATION | E17: 300647 | F17: =B17+C17+D17+E17 -> 300647 | G17: cr
A18: P.F.PAYABLE | E18: 393093 | F18: =B18+C18+D18+E18 -> 393093 | G18: cr
A19: Print Park | E19: 9924 | F19: =B19+C19+D19+E19 -> 9924 | G19: cr
A20: RENT PAYABLE | E20: 107343 | F20: =B20+C20+D20+E20 -> 107343 | G20: cr
A21: SALARY PAYABLE | E21: 2196990 | F21: =B21+C21+D21+E21 -> 2196990 | G21: cr
A22: Sri Amman Lath Works | E22: 40260 | F22: =B22+C22+D22+E22 -> 40260 | G22: cr
A23: TDS PAYABLE | C23: 14908 | E23: 527141 | F23: =B23+C23+D23+E23 -> 542049 | G23: cr
A24: Crs.for Purchase | B24: 498136 | C24: 1091393.5 | D24: 675527.7 | E24: 3004364.3 | F24: =E24+C24-D24-B24 -> 2922094.1
A25: Abirami Electricals | C25: 145553 | E25: 52435 | F25: =B25+C25+D25+E25 -> 197988 | G25: cr
A26: Acme Safetywears Ltd | E26: 79379 | F26: =B26+C26+D26+E26 -> 79379 | G26: cr
A27: Agar Engineers Pvt Ltd | E27: 74222 | F27: =B27+C27+D27+E27 -> 74222 | G27: cr
A28: Ambika Enterprises | B28: 240000 | F28: =B28+C28+D28+E28 -> 240000 | G28: dr
A29: Amman Motor Pipes | C29: 120354 | E29: 53650 | F29: =B29+C29+D29+E29 -> 174004 | G29: cr
A30: Bapu's Autotrade | D30: 9399 | F30: =B30+C30+D30+E30 -> 9399 | G30: dr
A31: B.Mangatram & Co | D31: 7727 | F31: =B31+C31+D31+E31 -> 7727 | G31: dr
A32: Chennai Steeel Company | E32: 386073 | F32: =B32+C32+D32+E32 -> 386073 | G32: cr
A33: Chennai Steel Company | C33: 7610 | F33: =B33+C33+D33+E33 -> 7610 | G33: cr
A34: Chettinad Cement Corpn Pvt Ltd | B34: 37250 | F34: =B34+C34+D34+E34 -> 37250 | G34: dr
A35: Chinnappa Chettiar & Sons | E35: 23128 | F35: =B35+C35+D35+E35 -> 23128 | G35: cr
A36: Delton Pneumatics | E36: 107676 | F36: =B36+C36+D36+E36 -> 107676 | G36: cr
A37: Dharani Hi Tech Project Pvt Ltd | B37: 31100 | F37: =B37+C37+D37+E37 -> 31100 | G37: dr
A38: Dynamic Prestress (I) Pvt Ltd Plant III | D38: 28642 | F38: =B38+C38+D38+E38 -> 28642 | G38: dr
A39: Fakhri Fasteners | E39: 46263 | F39: =B39+C39+D39+E39 -> 46263 | G39: cr
A40: Forestree India Pvt Ltd. | E40: 187186 | F40: =B40+C40+D40+E40 -> 187186 | G40: cr
...

Sheet Sheet3
B1: SEIL 12TO19
B2: Trial Balance
B3: 1-Apr-2017 to 31-Mar-2018
C4: SEIL 12TO19
B5: Particulars | C5: 1-Apr-2017 to 31-Mar-2018
C6: Closing Balance
C7: Debit | D7: Credit | M7: depreciation
B8: Capital Account | D8: 7147460 | M8: audit fees payable
B9: SHARE CAPITAL | D9: 7147460 | M9: Bhansali TDS
B10: Current Liabilities | C10: 7242945 | D10: 12860905 | M10: lic
B11: Crs. for Other Liabilities | M11: Nandakumar -Suspense
B12: Sundry Creditors | C12: 7242945 | D12: 12455493 | M12: Contract receipt-AVC and tirunandal
B13: CRS FOR EXPENSES | C13: 889138 | D13: 4263548.9
A14: OCL EXPPAY | B14: Air Tours & Travels | D14: 16 | E14: =-D14 -> -16 | F14: Other current liabilities-Expenses payable
A15: AFPAY | B15: AJOHN MORIS & CO | D15: =468288.93+412000 -> 880288.93 | E15: =-D15 -> -880288.93 | F15: Audit fees payable
A16: OCL EXPPAY | B16: Amman Earth Movers (MVM) | D16: 4202 | E16: =-D16 -> -4202 | F16: Other current liabilities-Expenses payable
A17: OCL EXPPAY | B17: G.L.Associate | D17: 900 | E17: =-D17 -> -900 | F17: Other current liabilities-Expenses payable
A18: OCL EXPPAY | B18: Hi-Tech Calibration Services | D18: 24150 | E18: =-D18 -> -24150 | F18: Other current liabilities-Expenses payable
A19: OCL EXPPAY | B19: Hitech Concrete Solution Chennai Pvt Ltd | D19: 46383 | E19: =-D19 -> -46383 | F19: Other current liabilities-Expenses payable
A20: OCL EXPPAY | B20: Interest Payable | D20: 12864 | E20: =-D20 -> -12864 | F20: Other current liabilities-Expenses payable
A21: STLA OADV | B21: JANNU ENGG.WORKS | C21: 47780 | E21: =C21 -> 47780 | F21: Short Term Loans and Advances - Other Advance
A22: OCL EXPPAY | B22: Janu Engg Works | D22: 5439 | E22: =-D22 -> -5439 | F22: Other current liabilities-Expenses payable
A23: OCL EXPPAY | B23: Jayam Engineering Works | D23: 1330 | E23: =-D23 -> -1330 | F23: Other current liabilities-Expenses payable
A24: OCL EXPPAY | B24: K K Enterprises | D24: 182380 | E24: =-D24 -> -182380 | F24: Other current liabilities-Expenses payable
A25: OCL EXPPAY | B25: KSR Generators | D25: 35000 | E25: =-D25 -> -35000 | F25: Other current liabilities-Expenses payable
A26: OCL EXPPAY | B26: LIC | D26: 252786 | E26: =-D26 -> -252786 | F26: Other current liabilities-Expenses payable
A27: OCL EXPPAY | B27: Manish Srivastava | D27: 17000 | E27: =-D27 -> -17000 | F27: Other current liabilities-Expenses payable
A28: OCL EXPPAY | B28: Mesha | D28: 111200 | E28: =-D28 -> -111200 | F28: Other current liabilities-Expenses payable
A29: STLA OADV | B29: N.K.BHANSALI & CO | C29: 450000 | E29: =C29 -> 450000 | F29: Short Term Loans and Advances - Other Advance
A30: OCL EXPPAY | B30: OUTSTANDING DIRECTORS REMUNERATION | D30: 404615 | E30: =-D30 -> -404615 | F30: Other current liabilities-Expenses payable
A31: OCL PFPAY | B31: P.F.PAYABLE | D31: 340410 | E31: =-D31 -> -340410 | F31: Other current liabilities-Expenses payable
A32: OCL EXPPAY | B32: Print Park | D32: 19833 | E32: =-D32 -> -19833 | F32: Other current liabilities-Expenses payable
A33: OCL EXPPAY | B33: Raghubhai D Chomal | D33: 20000 | E33: =-D33 -> -20000 | F33: Other current liabilities-Expenses payable
A34: STLA OADV | B34: Ramana M-CCCL Dhachepalli | C34: 300000 | E34: =C34 -> 300000 | F34: Short Term Loans and Advances - Other Advance
A35: OCL EXPPAY | B35: RENT PAYABLE | D35: 48834 | E35: =-D35 -> -48834 | F35: Other current liabilities-Expenses payable
A36: STLA OADV | B36: Sakthi Engineering Services | C36: 38738 | E36: =C36 -> 38738 | F36: Short Term Loans and Advances - Other Advance
A37: OCL EXPPAY | B37: SALARY PAYABLE | D37: 1835922 | E37: =-D37 -> -1835922 | F37: Other current liabilities-Expenses payable
A38: OCL EXPPAY | B38: Shri Electricals | D38: 19815 | E38: =-D38 -> -19815 | F38: Other current liabilities-Expenses payable
A39: OCL EXPPAY | B39: S.N.Mittal & Associates | D39: 5700 | E39: =-D39 -> -5700 | F39: Other current liabilities-Expenses payable
A40: STLA OADV | B40: S.R.COMPUTERS | C40: 13000 | E40: =C40 -> 13000 | F40: Short Term Loans and Advances - Other Advance
...

Sheet PL
A2: =BS!A2 -> M/s. Sathiapal Engineers (India) Private Limited (Formerly known as M/S Sathiapal Engineers (India) Limited)
A3: =BS!A3 -> CIN: U74210TN2002PLC048568
A4: =+BS!A4 -> New No. 57, Old No. 3, Canal Road, Kilpauk Garden Colony, Kilpauk, Chennai 600 010.
A6: STATEMENT OF PROFIT AND LOSS FOR THE YEAR ENDED 31st MARCH 2023
A8: Particulars | B8: Notes | C8: For the year 2022-23 | D8: For the year 2021-22
E9: =1000 -> 1000 | G9: =D11-D19-D20 -> 1.0609185e+08 | H9: =C11-C19-C20 -> 1.3005356e+08
A10: INCOME | F10: =1/1000 -> 0.001
A11: I.Revenue from Operations | B11: =Notes!B225 -> 18 | C11: =+Notes!J230 -> 4.1577423e+08 | D11: =351687.70804*1000 -> 3.5168771e+08
A12: II.Other Income | B12: =Notes!B233 -> 19 | C12: =+Notes!J239 -> 4701233.2 | D12: =8171.03452*1000 -> 8171034.5
G13: Year | H13: Value
A14: III.Total Revenue | C14: =C11+C12 -> 4.2047546e+08 | D14: =D11+D12 -> 3.5985874e+08 | E14: =C14*1000 -> 420475459260 | G14: 17-18 | H14: 35571205
G15: 18-19 | H15: 43435129
A16: IV.EXPENSES | G16: 20-21 | H16: 52056151
A17: Cost of Material Consumed | E17: =C19-E18 -> 1.0571339e+08
A18: Purchases of stock in trade | E18: =C19*F19 -> 2.3149728e+08 | G18: Total | H18: =H14+H15+H16 -> 1.3106249e+08
A19: Construction and Operating Expenses | B19: =Notes!B242 -> 20 | C19: =+Notes!J247 -> 3.3721067e+08 | D19: =241435.86174*(1000) -> 2.4143586e+08 | E19: =C19/C11 -> 0.81104274 | F19: =D19/D11 -> 0.6865064 | G19: Average | H19: =AVERAGE(H14:H16) -> 43687495
A20: Changes in Inventories of Finished Goods, Work in Progress and Stock in Trade | B20: =Notes!B250 -> 21 | C20: =+Notes!J260 -> -51490000 | D20: =4160*(1000) -> 4160000 | E20: =+C20+C19 -> 2.8572067e+08 | F20: =+D20+D19 -> 2.4559586e+08 | H20: 0.02
A21: Employee benefits expense | B21: =Notes!B263 -> 22 | C21: =+Notes!J271 -> 57635484 | D21: =51828.88898*(1000) -> 51828889 | E21: =+E20/C11 -> 0.68720149 | F21: =+F20/D11 -> 0.69833507 | G21: CSR | H21: =H19*H20 -> 873749.9
A22: Administrative and Other expenses | B22: =Notes!B274 -> 23 | C22: =+Notes!J307 -> 24412525 | D22: =22631.40145*(1000) -> 22631401 | E22: =+E21-1 -> -0.31279851 | F22: =+F21-1 -> -0.30166493
A23: Finance costs | B23: =Notes!#REF! -> #REF! | D23: =0*(1000) -> 0
A24: Write off of Assets | C24: =('Audit entries FY 22-23'!C79) -> 868251 | D24: =0*(1000) -> 0 | H24: =C24*2 -> 1736502
A25: Depreciation and Amortization | B25: 10 | C25: =Dep_Co!K26 -> 8219826.5 | D25: =9718.98258954644*(1000) -> 9718982.6 | E25: % | G25: =12765-C25 -> -8207061.5
A27: Total Expenses | C27: =SUM(C19:C25) -> 3.7685675e+08 | D27: =SUM(D19:D25) -> 3.2977513e+08
F28: -40008739 | G28: =F28-C30 -> -83627446 | H28: -1.15105e+08
G29: =262643608 -> 262643608 | H29: =C30-G29 -> -2.190249e+08
A30: (V)Profit / (Loss) Before Prior Period Items | C30: =C14-C27 -> 43618707 | D30: =30083.6078004535*1000 -> 30083608 | E30: =+C30/C11 -> 0.1049096 | F30: =1/1000 -> 0.001
A31: (VI)Prior period item: | C31: =('Audit entries FY 22-23'!D101) -> 2621516 | F31: 13245738 | G31: =F31-C30 -> -30372969 | H31: =1/1000 -> 0.001
D32: 0 | H32: =C30/C11 -> 0.1049096 | I32: =D30/D11 -> 0.085540686
A33: Profit / (Loss) Before Extraordinary Items & Tax
D34: 0
A35: (VII)Profit / (Loss) Before Extraordinary Items ,Exceptional Items and Tax | C35: =C30+C31 -> 46240223 | D35: =D30+D32-D34 -> 30083608 | F35: =C35/C11 -> 0.11121474
A36: (VIII)Extraordinary Items
A37: (VII)Profit / (Loss) Before Exceptional Items and Tax
A38: (VIII)Exceptional Items
A39: (IX)Profit before Tax
A40: (X)Less: Tax Expense | C40: =IT!E46 -> 10965295 | D40: =8443.3364*1000 -> 8443336.4 | G40: =C45-#REF! -> #REF!
A41: Current Tax | B41: 11 | C41: 0 | D41: 0
A42: Deferred Tax | B42: =+Notes!B139 -> 11 | C42: ='Audit entries FY 22-23'!D63 -> 742110.62 | D42: =-2016.03983785948*1000 -> -2016039.8 | F42: =C40-D40 -> 2521958.6
A45: Total Tax Expenses | C45: =C40+C42+C43 -> 11707406 | D45: =D40+D42+D43 -> 6427296.6
A47: (XI)Profit / (Loss) for the year | C47: =(C35-C45) -> 34532817 | D47: =D35-D45 -> 23656311 | E47: =C47/C11 -> 0.083056657 | F47: =D47/D11 -> 0.067265107 | G47: =C47-#REF! -> #REF! | H47: =1/1000 -> 0.001
...

Sheet Dep_Co
D3: M/S Sathiapal Engineers (India) Private Limited
D4: Formerly Known as M/S Sathiapal Engineers (India) Limited
H5: =BS!A3 -> CIN: U74210TN2002PLC048568
D6: =+Notes!B4 -> New No. 57, Old No. 3, Canal Road, Kilpauk Garden Colony, Kilpauk, Chennai 600 010.
D8: Note No:10 PROPERTY PLANT & EQUIPMENT: (AS PER COMPANIES ACT, 2013) | S8: 537374.21
S9: 1131993.8
D10: S. No. | E10: Name of the Block | F10: Gross Block | J10: DEPRECIATION | N10: Net Block | Q10: =1/1000 -> 0.001 | S10: 3298952
F11: As on 01.04.2022 | G11: Additions | H11: Deletion | I11: As on 31.03.2023 | J11: As on 01.04.2022 | K11: For the Period | L11: Deletion | M11: =I11 -> As on 31.03.2023 | N11: =I11 -> As on 31.03.2023 | O11: =F11 -> As on 01.04.2022
R12: Depreciation -IT | S12: =+Dep_IT!I23 -> 11820033
D13: 1 | E13: Building - WIP | F13: =868.251*1000 -> 868251 | G13: 0 | H13: =F13 -> 868251 | I13: =F13+G13-H13 -> 0 | J13: 0 | K13: =0 -> 0 | M13: =J13+K13 -> 0 | N13: =+I13-M13 -> 0 | R13: Depreciation-Co. | S13: =+K26 -> 8219826.5 | U13: 26312008 | V13: =U13-G15 -> -4778159.4
O14: =F14-J14 -> 0
D15: 2 | E15: Plant & Machinary | F15: =132856.773*1000 -> 1.3285677e+08 | G15: =(Sheet9!B21+Sheet9!B22)*1000 -> 31090167 | H15: 0 | I15: =F15+G15-H15 -> 1.6394694e+08 | J15: =88256.709*1000 -> 88256709 | K15: =(SUM('FA Register Final'!L169:L178)+SUM('FA Register Final'!L206:L242)+SUM('FA Register Final'!L10:L113)+SUM('FA Register Final'!L114:L143)) -> 4968320 | M15: =J15+K15 -> 93225029 | N15: =+I15-M15 -> 70721911 | O15: =F15-J15 -> 44600064 | P15: =K15-(F15/#REF!) -> #REF! | R15: Deferred Tax Asset | S15: =+S14*26% -> 0
D17: 3 | E17: Computers | F17: =4247.175*1000 -> 4247175 | G17: =(Sheet9!B18+Sheet9!B19)*1000 -> 247236.44 | H17: 0 | I17: =F17+G17-H17 -> 4494411.4 | J17: =3434.687*1000 -> 3434687 | K17: =(SUM('FA Register Final'!L159:L167)+SUM('FA Register Final'!L190:L197)+SUM('FA Register Final'!L3:L8)) -> 290888.03 | M17: =J17+K17 -> 3725575 | N17: =I17-M17 -> 768836.41 | O17: =F17-J17 -> 812488 | P17: =K17-(F17/#REF!) -> #REF! | S17: =+S16+S15 -> 0
D19: =D17+1 -> 4 | E19: Furnitures & Fixtures | F19: =950.451*(1000) -> 950451 | G19: 0 | H19: 0 | I19: =F19+G19-H19 -> 950451 | J19: =652.763*1000 -> 652763 | K19: 0 | M19: =J19+K19 -> 652763 | N19: =I19-M19 -> 297688 | O19: =F19-J19 -> 297688 | P19: =K19-(F19/#REF!) -> #REF!
F20: =0*(1000) -> 0
D21: =+D19+1 -> 5 | E21: Vehicles | F21: =19219.29*(1000) -> 19219290 | G21: =(Sheet9!B24)*1000 -> 1696884 | H21: =('Audit entries FY 22-23'!D70) -> 865919 | I21: =F21+G21-H21 -> 20050255 | J21: =10335.411*1000 -> 10335411 | K21: =(SUM('FA Register Final'!L182)+SUM('FA Register Final'!L245:L246)+SUM('FA Register Final'!I148:I150)) -> 2937535.4 | L21: =('Audit entries FY 22-23'!C69) -> 822623.05 | M21: =J21+K21-L21 -> 12450323 | N21: =I21-M21 -> 7599931.7 | O21: =F21-J21 -> 8883879 | P21: =K21-(F21/#REF!) -> #REF! | Q21: =H21-L21 -> 43295.95 | R21: 3474505 | S21: =O21-R21 -> 5409374
F22: =0*(1000) -> 0
D23: 6 | E23: Office Equipments | F23: =121.49*(1000) -> 121490 | G23: 0 | H23: 0 | I23: =F23+G23-H23 -> 121490 | J23: =21.818*1000 -> 21818 | K23: =('FA Register Final'!L188) -> 23083.1 | M23: =J23+K23 -> 44901.1 | N23: =I23-M23 -> 76588.9 | O23: =F23-J23 -> 99672
R25: 49451812 | S25: 6839713 | T25: =J19-N19 -> 355075
E26: TOTAL | F26: =SUM(F13:F23) -> 158263430 | G26: =SUM(G13:G23) -> 33034288 | H26: =SUM(H13:H23) -> 1734170 | I26: =SUM(I13:I23) -> 1.8956355e+08 | J26: =SUM(J13:J23) -> 102701388 | K26: =SUM(K13:K23) -> 8219826.5 | L26: =SUM(L13:L23) -> 822623.05 | M26: =SUM(M13:M23) -> 1.1009859e+08 | ... O26: =SUM(O13:O23) -> 54693791 | P26: =O26-N26 -> -24771165 | R26: 42612099 | S26: =R25-S25 -> 42612099
C27: =C28-G26 -> -4786299.8 | E27: =1000 -> 1000 | G27: =33034-G26 -> -33001254 | I27: =189563548/1000 -> 189563.55 | J27: =H21-L21 -> 43295.95 | K27: =I27-J27 -> 146267.6 | M27: =I26-M26 -> 79464956 | N27: =N26*1000 -> 7.9464956e+10 | O27: =K26-Dep_IT!I23*26% -> 5146617.9
C28: 28247988 | G28: 16072619 | I28: =I27-I26 -> -1.8937398e+08 | J28: =I26-M26 -> 79464956 | M28: =I26-M26 -> 79464956 | P28: 55562042
B44: 0 | C44: 1550
C51: 709574
C52: 20202
G141: =G28-G26 -> -16961669 | H141: 42094 | J141: 365 | M141: =78054+30601 -> 108655 | P141: =+G26-H26 -> 31300118 | Q141: =P141+L26 -> 32122741
N142: =565147/F21*H21 -> 25462.518 | P142: =K26 -> 8219826.5 | R142: =P141-P142+L26 -> 23902914
E143: Assets | F143: Date of Purchase | G143: Amount | H143: No. of Days till 31 mar 2014 | I143: Depreciation for the year | J143: Depreciation Rate | M143: >180 days | N143: =I19-J19 -> 297688 | O143: =I19*5% -> 47522.55 | P143: =P28+P141-P142 -> 78642333
E144: Plant & Machinery | N144: =N143-K19 -> 297688 | O144: =I19*5% -> 47522.55 | P144: =P143+L26 -> 79464956
E145: P & M 1 | F145: 41736 | G145: 70350 | H145: =$H$141-F145 -> 358 | I145: =G145*J145/$J$141*H145 -> 7134.685 | J145: 0.1034 | M145: =IF(H145>180,G145,0) -> 70350 | N145: =N143-N144 -> 0 | O145: =O143-O144 -> 0
E146: P & M 2 | F146: 41737 | G146: 77260 | H146: =$H$141-F146 -> 357 | I146: =G146*J146/$J$141*H146 -> 7813.5896 | J146: 0.1034 | M146: =IF(H146>180,G146,0) -> 77260
E147: P & M 3 | F147: 41747 | G147: 112931 | H147: =$H$141-F147 -> 347 | I147: =G147*J147/$J$141*H147 -> 11101.21 | J147: 0.1034 | M147: =IF(H147>180,G147,0) -> 112931
